Workbook

Sheet Painel
B2: PAINEL DE COMPRAS
B3: Visão consolidada dos gastos — tudo em fórmula: atualiza sozinho ao adicionar compras na aba Compras
B5: TOTAL GASTO | C5: ITENS | D5: TICKET MÉDIO | E5: MERCADOS | F5: PERÍODO
B6: =SUM(tblCompras[Total Pago]) -> 5963.22 | C6: =COUNTA(tblCompras[Produto]) -> 671 | D6: =IFERROR(B6/C6,0) -> 8.8870641 | E6: =SUMPRODUCT(1/COUNTIF(tblCompras[Mercado],tblCompras[Mercado])) -> 13 | F6: =DAY(MIN(tblCompras[Data]))&"/"&MONTH(MIN(tblCompras[Data]))&" → "&DAY(MAX(tblCompras[Data]))&"/"&MONTH(MAX(tblCompras[Data]))&"/"&YEAR(MAX(tblCompras[Data])) -> 2/5 → 10/8/2026
B9: ONDE VOCÊ ESTÁ GASTANDO
B10: Total por categoria (todas as categorias encontradas na aba Compras)
B12: Categoria | C12: Total | D12: %
B13: Mercearia | C13: =SUMIF(tblCompras[Categoria],B13,tblCompras[Total Pago]) -> 2590.26 | D13: =IFERROR(C13/$B$6,0) -> 0.4343727
B14: Laticinios | C14: =SUMIF(tblCompras[Categoria],B14,tblCompras[Total Pago]) -> 871.89 | D14: =IFERROR(C14/$B$6,0) -> 0.14621128
B15: Padaria | C15: =SUMIF(tblCompras[Categoria],B15,tblCompras[Total Pago]) -> 845.46 | D15: =IFERROR(C15/$B$6,0) -> 0.14177911
B16: Hortifruti | C16: =SUMIF(tblCompras[Categoria],B16,tblCompras[Total Pago]) -> 547.56 | D16: =IFERROR(C16/$B$6,0) -> 0.091822874
B17: Bebidas | C17: =SUMIF(tblCompras[Categoria],B17,tblCompras[Total Pago]) -> 311.84 | D17: =IFERROR(C17/$B$6,0) -> 0.052293895
B18: Carnes | C18: =SUMIF(tblCompras[Categoria],B18,tblCompras[Total Pago]) -> 205.97 | D18: =IFERROR(C18/$B$6,0) -> 0.034540064
B19: Higiene | C19: =SUMIF(tblCompras[Categoria],B19,tblCompras[Total Pago]) -> 164.96 | D19: =IFERROR(C19/$B$6,0) -> 0.027662907
B20: Limpeza | C20: =SUMIF(tblCompras[Categoria],B20,tblCompras[Total Pago]) -> 141.39 | D20: =IFERROR(C20/$B$6,0) -> 0.023710344
B21: Laticínios | C21: =SUMIF(tblCompras[Categoria],B21,tblCompras[Total Pago]) -> 73.92 | D21: =IFERROR(C21/$B$6,0) -> 0.012395987
B22: Saúde | C22: =SUMIF(tblCompras[Categoria],B22,tblCompras[Total Pago]) -> 51.15 | D22: =IFERROR(C22/$B$6,0) -> 0.0085775806
B23: Pet | C23: =SUMIF(tblCompras[Categoria],B23,tblCompras[Total Pago]) -> 43.81 | D23: =IFERROR(C23/$B$6,0) -> 0.0073467019
B24: Café | C24: =SUMIF(tblCompras[Categoria],B24,tblCompras[Total Pago]) -> 34.6 | D24: =IFERROR(C24/$B$6,0) -> 0.0058022344
... B28: Frutas | C28: =SUMIF(tblCompras[Categoria],B28,tblCompras[Total Pago]) -> 5.04 | D28: =IFERROR(C28/$B$6,0) -> 0.00084518096
B29: Total | C29: =SUM(C13:C28) -> 5963.22 | D29: =SUM(D13:D28) -> 1
B32: EVOLUÇÃO POR MÊS
B33: Quanto você gastou em cada mês (meses gerados automaticamente)
B35: Mês/Ano | C35: Total | D35: Itens
B36: =IF(Listas!E6="","",Listas!E6) -> mai/2026 | C36: =IF($B36="","",SUMIFS(tblCompras[Total Pago],tblCompras[Data],">="&Listas!$H$6,tblCompras[Data],"<="&EOMONTH(Listas!$H$6,0))) -> 2153.03 | D36: =IF($B36="","",COUNTIFS(tblCompras[Data],">="&Listas!$H$6,tblCompras[Data],"<="&EOMONTH(Listas!$H$6,0))) -> 240
B37: =IF(Listas!E7="","",Listas!E7) -> jun/2026 | C37: =IF($B37="","",SUMIFS(tblCompras[Total Pago],tblCompras[Data],">="&Listas!$H$7,tblCompras[Data],"<="&EOMONTH(Listas!$H$7,0))) -> 1585.03 | D37: =IF($B37="","",COUNTIFS(tblCompras[Data],">="&Listas!$H$7,tblCompras[Data],"<="&EOMONTH(Listas!$H$7,0))) -> 199
B38: =IF(Listas!E8="","",Listas!E8) -> jul/2026 | C38: =IF($B38="","",SUMIFS(tblCompras[Total Pago],tblCompras[Data],">="&Listas!$H$8,tblCompras[Data],"<="&EOMONTH(Listas!$H$8,0))) -> 1969.23 | D38: =IF($B38="","",COUNTIFS(tblCompras[Data],">="&Listas!$H$8,tblCompras[Data],"<="&EOMONTH(Listas!$H$8,0))) -> 207
B39: =IF(Listas!E9="","",Listas!E9) -> ago/2026 | C39: =IF($B39="","",SUMIFS(tblCompras[Total Pago],tblCompras[Data],">="&Listas!$H$9,tblCompras[Data],"<="&EOMONTH(Listas!$H$9,0))) -> 255.93 | D39: =IF($B39="","",COUNTIFS(tblCompras[Data],">="&Listas!$H$9,tblCompras[Data],"<="&EOMONTH(Listas!$H$9,0))) -> 25
B40: =IF(Listas!E10="","",Listas!E10) | C40: =IF($B40="","",SUMIFS(tblCompras[Total Pago],tblCompras[Data],">="&Listas!$H$10,tblCompras[Data],"<="&EOMONTH(Listas!$H$10,0))) | D40: =IF($B40="","",COUNTIFS(tblCompras[Data],">="&Listas!$H$10,tblCompras[Data],"<="&EOMONTH(Listas!$H$10,0)))
B41: =IF(Listas!E11="","",Listas!E11) | C41: =IF($B41="","",SUMIFS(tblCompras[Total Pago],tblCompras[Data],">="&Listas!$H$11,tblCompras[Data],"<="&EOMONTH(Listas!$H$11,0))) | D41: =IF($B41="","",COUNTIFS(tblCompras[Data],">="&Listas!$H$11,tblCompras[Data],"<="&EOMONTH(Listas!$H$11,0)))
B42: =IF(Listas!E12="","",Listas!E12) | C42: =IF($B42="","",SUMIFS(tblCompras[Total Pago],tblCompras[Data],">="&Listas!$H$12,tblCompras[Data],"<="&EOMONTH(Listas!$H$12,0))) | D42: =IF($B42="","",COUNTIFS(tblCompras[Data],">="&Listas!$H$12,tblCompras[Data],"<="&EOMONTH(Listas!$H$12,0)))
B43: =IF(Listas!E13="","",Listas!E13) | C43: =IF($B43="","",SUMIFS(tblCompras[Total Pago],tblCompras[Data],">="&Listas!$H$13,tblCompras[Data],"<="&EOMONTH(Listas!$H$13,0))) | D43: =IF($B43="","",COUNTIFS(tblCompras[Data],">="&Listas!$H$13,tblCompras[Data],"<="&EOMONTH(Listas!$H$13,0)))
B44: =IF(Listas!E14="","",Listas!E14) | C44: =IF($B44="","",SUMIFS(tblCompras[Total Pago],tblCompras[Data],">="&Listas!$H$14,tblCompras[Data],"<="&EOMONTH(Listas!$H$14,0))) | D44: =IF($B44="","",COUNTIFS(tblCompras[Data],">="&Listas!$H$14,tblCompras[Data],"<="&EOMONTH(Listas!$H$14,0)))
B45: =IF(Listas!E15="","",Listas!E15) | C45: =IF($B45="","",SUMIFS(tblCompras[Total Pago],tblCompras[Data],">="&Listas!$H$15,tblCompras[Data],"<="&EOMONTH(Listas!$H$15,0))) | D45: =IF($B45="","",COUNTIFS(tblCompras[Data],">="&Listas!$H$15,tblCompras[Data],"<="&EOMONTH(Listas!$H$15,0)))
B46: =IF(Listas!E16="","",Listas!E16) | C46: =IF($B46="","",SUMIFS(tblCompras[Total Pago],tblCompras[Data],">="&Listas!$H$16,tblCompras[Data],"<="&EOMONTH(Listas!$H$16,0))) | D46: =IF($B46="","",COUNTIFS(tblCompras[Data],">="&Listas!$H$16,tblCompras[Data],"<="&EOMONTH(Listas!$H$16,0)))
B47: =IF(Listas!E17="","",Listas!E17) | C47: =IF($B47="","",SUMIFS(tblCompras[Total Pago],tblCompras[Data],">="&Listas!$H$17,tblCompras[Data],"<="&EOMONTH(Listas!$H$17,0))) | D47: =IF($B47="","",COUNTIFS(tblCompras[Data],">="&Listas!$H$17,tblCompras[Data],"<="&EOMONTH(Listas!$H$17,0)))
B48: Total | C48: =SUM(C36:C47) -> 5963.22 | D48: =SUM(D36:D47) -> 671
B51: POR MERCADO
B52: Quanto você gastou em cada lugar
B54: Mercado | C54: Total | D54: Itens | E54: Ticket | F54: %
...

Sheet Análise Dinâmica
B2: ANÁLISE DINÂMICA
B3: Escolha os filtros abaixo (células amarelas) — todos os números e gráficos recalculam na hora
M4: aux
B5: MÊS/ANO | D5: CATEGORIA | F5: MERCADO | M5: =IFERROR(MATCH($B$6,Listas!$E$6:$E$17,0),0) -> 3
B6: jul/2026 | D6: (Todos) | F6: (Todos) | M6: =IF($M$5=0,DATE(1900,1,1),EOMONTH(MIN(tblCompras[Data]),$M$5-2)+1) -> 46204
M7: =IF($M$5=0,DATE(9999,12,31),EOMONTH($M$6,0)) -> 46234
B8: TOTAL (filtro) | C8: ITENS (filtro) | D8: TICKET MÉDIO | E8: % DO TOTAL GERAL
B9: =SUMIFS(tblCompras[Total Pago],tblCompras[Data],">="&$M$6,tblCompras[Data],"<="&$M$7,tblCompras[Categoria],IF($D$6="(Todos)","*",$D$6),tblCompras[Mercado],IF($F$6="(Todos)","*",$F$6)) -> 1969.23 | C9: =COUNTIFS(tblCompras[Data],">="&$M$6,tblCompras[Data],"<="&$M$7,tblCompras[Categoria],IF($D$6="(Todos)","*",$D$6),tblCompras[Mercado],IF($F$6="(Todos)","*",$F$6)) -> 207 | D9: =IFERROR(B9/C9,0) -> 9.5131884 | E9: =IFERROR(B9/SUM(tblCompras[Total Pago]),0) -> 0.33022931
B12: GASTO POR CATEGORIA
B13: Aplica os filtros de mês e mercado
B15: Categoria | C15: Total
B16: Mercearia | C16: =SUMIFS(tblCompras[Total Pago],tblCompras[Categoria],$B16,tblCompras[Data],">="&$M$6,tblCompras[Data],"<="&$M$7,tblCompras[Mercado],IF($F$6="(Todos)","*",$F$6)) -> 862.17
B17: Laticinios | C17: =SUMIFS(tblCompras[Total Pago],tblCompras[Categoria],$B17,tblCompras[Data],">="&$M$6,tblCompras[Data],"<="&$M$7,tblCompras[Mercado],IF($F$6="(Todos)","*",$F$6)) -> 338.09
B18: Padaria | C18: =SUMIFS(tblCompras[Total Pago],tblCompras[Categoria],$B18,tblCompras[Data],">="&$M$6,tblCompras[Data],"<="&$M$7,tblCompras[Mercado],IF($F$6="(Todos)","*",$F$6)) -> 332.25
B19: Hortifruti | C19: =SUMIFS(tblCompras[Total Pago],tblCompras[Categoria],$B19,tblCompras[Data],">="&$M$6,tblCompras[Data],"<="&$M$7,tblCompras[Mercado],IF($F$6="(Todos)","*",$F$6)) -> 169.31
B20: Bebidas | C20: =SUMIFS(tblCompras[Total Pago],tblCompras[Categoria],$B20,tblCompras[Data],">="&$M$6,tblCompras[Data],"<="&$M$7,tblCompras[Mercado],IF($F$6="(Todos)","*",$F$6)) -> 122.28
B21: Carnes | C21: =SUMIFS(tblCompras[Total Pago],tblCompras[Categoria],$B21,tblCompras[Data],">="&$M$6,tblCompras[Data],"<="&$M$7,tblCompras[Mercado],IF($F$6="(Todos)","*",$F$6)) -> 69.08
B22: Higiene | C22: =SUMIFS(tblCompras[Total Pago],tblCompras[Categoria],$B22,tblCompras[Data],">="&$M$6,tblCompras[Data],"<="&$M$7,tblCompras[Mercado],IF($F$6="(Todos)","*",$F$6)) -> 38.82
B23: Limpeza | C23: =SUMIFS(tblCompras[Total Pago],tblCompras[Categoria],$B23,tblCompras[Data],">="&$M$6,tblCompras[Data],"<="&$M$7,tblCompras[Mercado],IF($F$6="(Todos)","*",$F$6)) -> 37.23
B24: Laticínios | C24: =SUMIFS(tblCompras[Total Pago],tblCompras[Categoria],$B24,tblCompras[Data],">="&$M$6,tblCompras[Data],"<="&$M$7,tblCompras[Mercado],IF($F$6="(Todos)","*",$F$6)) -> 0
B25: Saúde | C25: =SUMIFS(tblCompras[Total Pago],tblCompras[Categoria],$B25,tblCompras[Data],">="&$M$6,tblCompras[Data],"<="&$M$7,tblCompras[Mercado],IF($F$6="(Todos)","*",$F$6)) -> 0
B26: Pet | C26: =SUMIFS(tblCompras[Total Pago],tblCompras[Categoria],$B26,tblCompras[Data],">="&$M$6,tblCompras[Data],"<="&$M$7,tblCompras[Mercado],IF($F$6="(Todos)","*",$F$6)) -> 0
B27: Café | C27: =SUMIFS(tblCompras[Total Pago],tblCompras[Categoria],$B27,tblCompras[Data],">="&$M$6,tblCompras[Data],"<="&$M$7,tblCompras[Mercado],IF($F$6="(Todos)","*",$F$6)) -> 0
... B31: Frutas | C31: =SUMIFS(tblCompras[Total Pago],tblCompras[Categoria],$B31,tblCompras[Data],">="&$M$6,tblCompras[Data],"<="&$M$7,tblCompras[Mercado],IF($F$6="(Todos)","*",$F$6)) -> 0
B32: Total | C32: =SUM(C16:C31) -> 1969.23
B35: EVOLUÇÃO MENSAL
B36: Aplica os filtros de categoria e mercado
B38: Mês/Ano | C38: Total
B39: =IF(Listas!E6="","",Listas!E6) -> mai/2026 | C39: =IF($B39="","",SUMIFS(tblCompras[Total Pago],tblCompras[Data],">="&Listas!$H$6,tblCompras[Data],"<="&EOMONTH(Listas!$H$6,0),tblCompras[Categoria],IF($D$6="(Todos)","*",$D$6),tblCompras[Mercado],IF($F$6="(Todos)","*",$F$6))) -> 2153.03
B40: =IF(Listas!E7="","",Listas!E7) -> jun/2026 | C40: =IF($B40="","",SUMIFS(tblCompras[Total Pago],tblCompras[Data],">="&Listas!$H$7,tblCompras[Data],"<="&EOMONTH(Listas!$H$7,0),tblCompras[Categoria],IF($D$6="(Todos)","*",$D$6),tblCompras[Mercado],IF($F$6="(Todos)","*",$F$6))) -> 1585.03
B41: =IF(Listas!E8="","",Listas!E8) -> jul/2026 | C41: =IF($B41="","",SUMIFS(tblCompras[Total Pago],tblCompras[Data],">="&Listas!$H$8,tblCompras[Data],"<="&EOMONTH(Listas!$H$8,0),tblCompras[Categoria],IF($D$6="(Todos)","*",$D$6),tblCompras[Mercado],IF($F$6="(Todos)","*",$F$6))) -> 1969.23
B42: =IF(Listas!E9="","",Listas!E9) -> ago/2026 | C42: =IF($B42="","",SUMIFS(tblCompras[Total Pago],tblCompras[Data],">="&Listas!$H$9,tblCompras[Data],"<="&EOMONTH(Listas!$H$9,0),tblCompras[Categoria],IF($D$6="(Todos)","*",$D$6),tblCompras[Mercado],IF($F$6="(Todos)","*",$F$6))) -> 255.93
B43: =IF(Listas!E10="","",Listas!E10) | C43: =IF($B43="","",SUMIFS(tblCompras[Total Pago],tblCompras[Data],">="&Listas!$H$10,tblCompras[Data],"<="&EOMONTH(Listas!$H$10,0),tblCompras[Categoria],IF($D$6="(Todos)","*",$D$6),tblCompras[Mercado],IF($F$6="(Todos)","*",$F$6)))
B44: =IF(Listas!E11="","",Listas!E11) | C44: =IF($B44="","",SUMIFS(tblCompras[Total Pago],tblCompras[Data],">="&Listas!$H$11,tblCompras[Data],"<="&EOMONTH(Listas!$H$11,0),tblCompras[Categoria],IF($D$6="(Todos)","*",$D$6),tblCompras[Mercado],IF($F$6="(Todos)","*",$F$6)))
B45: =IF(Listas!E12="","",Listas!E12) | C45: =IF($B45="","",SUMIFS(tblCompras[Total Pago],tblCompras[Data],">="&Listas!$H$12,tblCompras[Data],"<="&EOMONTH(Listas!$H$12,0),tblCompras[Categoria],IF($D$6="(Todos)","*",$D$6),tblCompras[Mercado],IF($F$6="(Todos)","*",$F$6)))
B46: =IF(Listas!E13="","",Listas!E13) | C46: =IF($B46="","",SUMIFS(tblCompras[Total Pago],tblCompras[Data],">="&Listas!$H$13,tblCompras[Data],"<="&EOMONTH(Listas!$H$13,0),tblCompras[Categoria],IF($D$6="(Todos)","*",$D$6),tblCompras[Mercado],IF($F$6="(Todos)","*",$F$6)))
B47: =IF(Listas!E14="","",Listas!E14) | C47: =IF($B47="","",SUMIFS(tblCompras[Total Pago],tblCompras[Data],">="&Listas!$H$14,tblCompras[Data],"<="&EOMONTH(Listas!$H$14,0),tblCompras[Categoria],IF($D$6="(Todos)","*",$D$6),tblCompras[Mercado],IF($F$6="(Todos)","*",$F$6)))
B48: =IF(Listas!E15="","",Listas!E15) | C48: =IF($B48="","",SUMIFS(tblCompras[Total Pago],tblCompras[Data],">="&Listas!$H$15,tblCompras[Data],"<="&EOMONTH(Listas!$H$15,0),tblCompras[Categoria],IF($D$6="(Todos)","*",$D$6),tblCompras[Mercado],IF($F$6="(Todos)","*",$F$6)))
B49: =IF(Listas!E16="","",Listas!E16) | C49: =IF($B49="","",SUMIFS(tblCompras[Total Pago],tblCompras[Data],">="&Listas!$H$16,tblCompras[Data],"<="&EOMONTH(Listas!$H$16,0),tblCompras[Categoria],IF($D$6="(Todos)","*",$D$6),tblCompras[Mercado],IF($F$6="(Todos)","*",$F$6)))
B50: =IF(Listas!E17="","",Listas!E17) | C50: =IF($B50="","",SUMIFS(tblCompras[Total Pago],tblCompras[Data],">="&Listas!$H$17,tblCompras[Data],"<="&EOMONTH(Listas!$H$17,0),tblCompras[Categoria],IF($D$6="(Todos)","*",$D$6),tblCompras[Mercado],IF($F$6="(Todos)","*",$F$6)))
...

Sheet Nota Fiscal
B2: NOTAS FISCAIS — CONFERÊNCIA
B3: Uma nota = um bloco no padrão fixo. Soma, diferença e status são fórmulas: basta digitar os itens e o total do cupom.
B4: Para lançar uma nota nova: copie o BLOCO MODELO inteiro (da barra do título até a linha em branco), cole no fim da aba e preencha as células amarelas.
B5: Lembrete: os itens também precisam ser lançados na aba Compras — é ela que alimenta o Painel e a Análise Dinâmica.
B7: ÍNDICE DAS NOTAS
B8: Resumo automático — clique no nº para ir até a nota
B10: Nº | C10: Data | D10: Mercado | E10: Documento | F10: Pagamento | G10: Itens | H10: Total oficial | I10: Soma itens | J10: Dif. (R$) | K10: Status
B11: 001 | C11: =C103 -> 46144 | D11: =C102 -> Crystal | E11: =G102 -> NFC-e 000052920 série 017 | F11: =G103 -> Cartão de Crédito | G11: =C105 -> 3 | H11: =G104 -> 27.67 | I11: =G105 -> 27.67 | J11: =G106 -> 0 | K11: =IF(AND(OR(C104="",C104=C105,C104=C106),ABS(N(G106))<=0.05),"OK","Revisar") -> OK
B12: 002 | C12: =C115 -> 46146 | D12: =C114 -> Supermercados Nori | E12: =G114 -> Cupom 00077650 / NFC-e 24610 Série 004 | F12: =G115 -> Cartão de Crédito | G12: =C117 -> 21 | H12: =G116 -> 184.05 | I12: =G117 -> 184.05 | J12: =G118 -> 0 | K12: =IF(AND(OR(C116="",C116=C117,C116=C118),ABS(N(G118))<=0.05),"OK","Revisar") -> OK
B13: 003 | C13: =C145 -> 46147 | D13: =C144 -> Supermercados Nori | E13: =G144 -> Cupom 91475 | F13: =G145 -> Cartão de Crédito | G13: =C147 -> 33 | H13: =G146 -> 301.86 | I13: =G147 -> 301.76 | J13: =G148 -> 0.1 | K13: =IF(AND(OR(C146="",C146=C147,C146=C148),ABS(N(G148))<=0.05),"OK","Revisar") -> Revisar
B14: 004 | C14: =C187 -> 46148 | D14: =C186 -> Varejao Monteverde | E14: =G186 -> NFC-e 2410 série 2 | F14: =G187 -> Cartão de Crédito | G14: =C189 -> 3 | H14: =G188 -> 17.69 | I14: =G189 -> 17.69 | J14: =G190 -> 0 | K14: =IF(AND(OR(C188="",C188=C189,C188=C190),ABS(N(G190))<=0.05),"OK","Revisar") -> OK
B15: 005 | C15: =C199 -> 46151 | D15: =C198 -> Supermercado Canesin | E15: =G198 -> NFC-e 000038274 série 301 | F15: =G199 -> Cartão de Crédito | G15: =C201 -> 2 | H15: =G200 -> 16.18 | I15: =G201 -> 16.18 | J15: =G202 -> 0 | K15: =IF(AND(OR(C200="",C200=C201,C200=C202),ABS(N(G202))<=0.05),"OK","Revisar") -> OK
B16: 006 | C16: =C210 -> 46152 | D16: =C209 -> Casa de Carnes Barao da Carne | E16: =G209 -> Pedido 083825 (Orçamento - Sem Valor Fiscal) | F16: =G210 -> Cartão de Crédito | G16: =C212 -> 2 | H16: =G211 -> 78.48 | I16: =G212 -> 78.48 | J16: =G213 -> 0 | K16: =IF(AND(OR(C211="",C211=C212,C211=C213),ABS(N(G213))<=0.05),"OK","Revisar") -> OK
B17: 007 | C17: =C221 -> 46152 | D17: =C220 -> Varejao Monteverde | E17: =G220 -> NFC-e 8933 série 1 | F17: =G221 -> Cartão de Crédito | G17: =C223 -> 2 | H17: =G222 -> 13.73 | I17: =G223 -> 13.73 | J17: =G224 -> 0 | K17: =IF(AND(OR(C222="",C222=C223,C222=C224),ABS(N(G224))<=0.05),"OK","Revisar") -> OK
B18: 008 | C18: =C232 -> 46152 | D18: =C231 -> Real Atacamix | E18: =G231 -> Pedido 103009583 Oper. 03 | F18: =G232 -> Cartão de Crédito | G18: =C234 -> 3 | H18: =G233 -> 39.96 | I18: =G234 -> 39.96 | J18: =G235 -> 0 | K18: =IF(AND(OR(C233="",C233=C234,C233=C235),ABS(N(G235))<=0.05),"OK","Revisar") -> OK
B19: 009 | C19: =C244 -> 46152 | D19: =C243 -> Andre Supermercado | E19: =G243 -> Cupom 0900212 PDV 03 | F19: =G244 -> Cartão de Crédito | G19: =C246 -> 3 | H19: =G245 -> 18.18 | I19: =G246 -> 18.18 | J19: =G247 -> 0 | K19: =IF(AND(OR(C245="",C245=C246,C245=C247),ABS(N(G247))<=0.05),"OK","Revisar") -> OK
B20: 010 | C20: =C256 -> 46152 | D20: =C255 -> Supermercados Nori | E20: =G255 -> Cupom 00083585 NFC-e 27580 Serie 014 | F20: =G256 -> PIX | G20: =C258 -> 3 | H20: =G257 -> 93.46 | I20: =G258 -> 93.46 | J20: =G259 -> 0 | K20: =IF(AND(OR(C257="",C257=C258,C257=C259),ABS(N(G259))<=0.05),"OK","Revisar") -> OK
B21: 011 | C21: =C268 -> 46156 | D21: =C267 -> Andre Novato Ribeiro | E21: =G267 -> Cupom Nota 36741 | F21: =G268 -> Cartão de Crédito | G21: =C270 -> 2 | H21: =G269 -> 39.98 | I21: =G270 -> 39.98 | J21: =G271 -> 0 | K21: =IF(AND(OR(C269="",C269=C270,C269=C271),ABS(N(G271))<=0.05),"OK","Revisar") -> OK
B22: 012 | C22: =C279 -> 46156 | D22: =C278 -> Varejao Monteverde | E22: =G278 -> Cupom NFC-e 3067 Série 3 | F22: =G279 -> Cartão de Crédito | G22: =C281 -> 4 | H22: =G280 -> 30.83 | I22: =G281 -> 30.83 | J22: =G282 -> 0 | K22: =IF(AND(OR(C280="",C280=C281,C280=C282),ABS(N(G282))<=0.05),"OK","Revisar") -> OK
B23: 013 | C23: =C292 -> 46157 | D23: =C291 -> Supermercados Nori | E23: =G291 -> Cupom Cupom 00065290 | F23: =G292 -> Cartão de Crédito | G23: =C294 -> 50 | H23: =G293 -> 370.63 | I23: =G294 -> 370.63 | J23: =G295 -> 0 | K23: =IF(AND(OR(C293="",C293=C294,C293=C295),ABS(N(G295))<=0.05),"OK","Revisar") -> OK
B24: 014 | C24: =C351 -> 46158 | D24: =C350 -> Varejao Nova Brasil | E24: =G350 -> Cupom Não Fiscal - Terminal 0002 - Vitoria | F24: =G351 -> Não informado | G24: =C353 -> 5 | H24: =G352 -> 48.52 | I24: =G353 -> 48.52 | J24: =G354 -> 0 | K24: =IF(AND(OR(C352="",C352=C353,C352=C354),ABS(N(G354))<=0.05),"OK","Revisar") -> OK
B25: 015 | C25: =C365 -> 46159 | D25: =C364 -> Supermercados Nori | E25: =G364 -> Cupom 00071051 NFC-e 22022 Série 007 | F25: =G365 -> Cartão de Crédito | G25: =C367 -> 9 | H25: =G366 -> 102.74 | I25: =G367 -> 102.74 | J25: =G368 -> 0 | K25: =IF(AND(OR(C366="",C366=C367,C366=C368),ABS(N(G368))<=0.05),"OK","Revisar") -> OK
B26: 016 | C26: =C383 -> 46161 | D26: =C382 -> Supermercado Canesin | E26: =G382 -> Cupom (NFC-e) 000050028 / Série 302 | F26: =G383 -> Cartão de Crédito | G26: =C385 -> 2 | H26: =G384 -> 17.05 | I26: =G385 -> 17.05 | J26: =G386 -> 0 | K26: =IF(AND(OR(C384="",C384=C385,C384=C386),ABS(N(G386))<=0.05),"OK","Revisar") -> OK
B27: 017 | C27: =C394 -> 46162 | D27: =C393 -> Andre Eduardo Hipolito | E27: =G393 -> Cupom DOC 038073 / COO 036256 (não fiscal) | F27: =G394 -> Cartão de Crédito | G27: =C396 -> 4 | H27: =G395 -> 36 | I27: =G396 -> 36 | J27: =G397 -> 0 | K27: =IF(AND(OR(C395="",C395=C396,C395=C397),ABS(N(G397))<=0.05),"OK","Revisar") -> OK
B28: 018 | C28: =C407 -> 46163 | D28: =C406 -> Varejao Monteverde | E28: =G406 -> Cupom NFC-e nº 3243 / Série 3 | F28: =G407 -> Cartão de Crédito | G28: =C409 -> 5 | H28: =G408 -> 33.34 | I28: =G409 -> 33.34 | J28: =G410 -> 0 | K28: =IF(AND(OR(C408="",C408=C409,C408=C410),ABS(N(G410))<=0.05),"OK","Revisar") -> OK
B29: 019 | C29: =C421 -> 46168 | D29: =C420 -> Varejao Monteverde | E29: =G420 -> Cupom COD: 1492272 PDV1 | F29: =G421 -> Dinheiro | G29: =C423 -> 5 | H29: =G422 -> 33.25 | I29: =G423 -> 33.25 | J29: =G424 -> 0 | K29: =IF(AND(OR(C422="",C422=C423,C422=C424),ABS(N(G424))<=0.05),"OK","Revisar") -> OK
B30: 020 | C30: =C435 -> 46168 | D30: =C434 -> Andre Eduardo Hipolito | E30: =G434 -> Cupom NFC-e nº 000002266 / Série 001 / DOC 040187 | F30: =G435 -> Dinheiro | G30: =C437 -> 1 | H30: =G436 -> 5.85 | I30: =G437 -> 5.85 | J30: =G438 -> 0 | K30: =IF(AND(OR(C436="",C436=C437,C436=C438),ABS(N(G438))<=0.05),"OK","Revisar") -> OK
B31: 021 | C31: =C445 -> 46169 | D31: =C444 -> Supermercado Canesin | E31: =G444 -> NFC-e 000042390 — Série 301 | F31: =G445 -> Dinheiro R$ 100,00 / Troco R$ 86,02 | G31: =C447 -> 2 | H31: =G446 -> 13.98 | I31: =G447 -> 13.98 | J31: =G448 -> 0 | K31: =IF(AND(OR(C446="",C446=C447,C446=C448),ABS(N(G448))<=0.05),"OK","Revisar") -> OK
B32: 022 | C32: =C456 -> 46169 | D32: =C455 -> Andre Eduardo Hipolito | E32: =G455 -> Cupom DOC 040540 — COO 040075 | F32: =G456 -> Dinheiro R$ 21,00 / Troco R$ 0,08 | G32: =C458 -> 3 | H32: =G457 -> 20.92 | I32: =G458 -> 20.92 | J32: =G459 -> 0 | K32: =IF(AND(OR(C457="",C457=C458,C457=C459),ABS(N(G459))<=0.05),"OK","Revisar") -> OK
B33: 023 | C33: =C468 -> 46170 | D33: =C467 -> Varejao Monteverde | E33: =G467 -> Cupom COD: 1492588 — PDV1 | F33: =G468 -> Dinheiro R$ 50,55 / Troco R$ 28,00 | G33: =C470 -> 3 | H33: =G469 -> 22.55 | I33: =G470 -> 22.55 | J33: =G471 -> 0 | K33: =IF(AND(OR(C469="",C469=C470,C469=C471),ABS(N(G471))<=0.05),"OK","Revisar") -> OK
B34: 024 | C34: =C480 -> 46171 | D34: =C479 -> Varejao Monteverde | E34: =G479 -> Cupom COD: 1492747 — PDV2 | F34: =G480 -> Dinheiro R$ 17,00 / Troco R$ 0,20 | G34: =C482 -> 1 | H34: =G481 -> 16.8 | I34: =G482 -> 16.8 | J34: =G483 -> 0 | K34: =IF(AND(OR(C481="",C481=C482,C481=C483),ABS(N(G483))<=0.05),"OK","Revisar") -> OK
B35: 025 | C35: =C490 -> 46171 | D35: =C489 -> Supermercado Canesin | E35: =G489 -> Cupom NFC-e nº 52295 / Série 302 | F35: =G490 -> Dinheiro | G35: =C492 -> 12 | H35: =G491 -> 78.21 | I35: =G492 -> 78.21 | J35: =G493 -> 0 | K35: =IF(AND(OR(C491="",C491=C492,C491=C493),ABS(N(G493))<=0.05),"OK","Revisar") -> OK
B36: 026 | C36: =C511 -> 46173 | D36: =C510 -> Supermercados Nori | E36: =G510 -> Cupom Cupom 00073882 | F36: =G511 -> Não informado | G36: =C513 -> 44 | H36: =G512 -> 289.12 | I36: =G513 -> 289.12 | J36: =G514 -> 0 | K36: =IF(AND(OR(C512="",C512=C513,C512=C514),ABS(N(G514))<=0.05),"OK","Revisar") -> OK
B37: 027 | C37: =C564 -> 46173 | D37: =C563 -> Varejao Monteverde | E37: =G563 -> NFC-e NFC-e nº 9592 / Série 1 | F37: =G564 -> Cartão de Crédito | G37: =C566 -> 4 | H37: =G565 -> 23.9 | I37: =G566 -> 23.9 | J37: =G567 -> 0 | K37: =IF(AND(OR(C565="",C565=C566,C565=C567),ABS(N(G567))<=0.05),"OK","Revisar") -> OK
B38: 028 | C38: =C577 -> 46176 | D38: =C576 -> Varejao Monteverde | E38: =G576 -> NFC-e NFC-e nº 3087 / Série 2 | F38: =G577 -> Cartão de Crédito | G38: =C579 -> 13 | H38: =G578 -> 78.38 | I38: =G579 -> 78.38 | J38: =G580 -> 0 | K38: =IF(AND(OR(C578="",C578=C579,C578=C580),ABS(N(G580))<=0.05),"OK","Revisar") -> OK
B39: 029 | C39: =C599 -> 46176 | D39: =C598 -> Supermercados Nori | E39: =G598 -> Cupom / NFC-e Cupom 68001 · NFC-e nº 20926 / Série 005 | F39: =G599 -> Cartão de Crédito | G39: =C601 -> 47 | H39: =G600 -> 336.92 | I39: =G601 -> 336.92 | J39: =G602 -> 0 | K39: =IF(AND(OR(C600="",C600=C601,C600=C602),ABS(N(G602))<=0.05),"OK","Revisar") -> OK
B40: 030 | C40: =C655 -> 46177 | D40: =C654 -> Supermercado Canesin | E40: =G654 -> Cupom (NFC-e) 000053664 / Série 302 | F40: =G655 -> Cartão de Crédito | G40: =C657 -> 5 | H40: =G656 -> 26.73 | I40: =G657 -> 26.73 | J40: =G658 -> 0 | K40: =IF(AND(OR(C656="",C656=C657,C656=C658),ABS(N(G658))<=0.05),"OK","Revisar") -> OK
B41: 031 | C41: =C669 -> 46179 | D41: =C668 -> Supermercados Nori | E41: =G668 -> Cupom (NFC-e) 000034682 / Série 002 (Cupom 00103940) | F41: =G669 -> Cartão de Crédito | G41: =C671 -> 16 | H41: =G670 -> 162.37 | I41: =G671 -> 162.37 | J41: =G672 -> 0 | K41: =IF(AND(OR(C670="",C670=C671,C670=C672),ABS(N(G672))<=0.05),"OK","Revisar") -> OK
B42: 032 | C42: =C694 -> 46183 | D42: =C693 -> Supermercado Canesin | E42: =G693 -> Cupom (NFC-e) 000054990 / Série 302 (Cupom 093663) | F42: =G694 -> Cartão de Crédito | G42: =C696 -> 2 | H42: =G695 -> 15.46 | I42: =G696 -> 15.46 | J42: =G697 -> 0 | K42: =IF(AND(OR(C695="",C695=C696,C695=C697),ABS(N(G697))<=0.05),"OK","Revisar") -> OK
B43: 033 | C43: =C705 -> 46183 | D43: =C704 -> Lanchoti e Martins | E43: =G704 -> Cupom (NFC-e) 000235703 / Série 001 | F43: =G705 -> Cartão de Crédito | G43: =C707 -> 2 | H43: =G706 -> 51.15 | I43: =G707 -> 51.15 | J43: =G708 -> 0 | K43: =IF(AND(OR(C706="",C706=C707,C706=C708),ABS(N(G708))<=0.05),"OK","Revisar") -> OK
...

Sheet Compras
A1: Compras
A2: Tabela operacional. Cada linha = um item comprado. Coluna B (Mês/Ano) facilita a comparação entre meses.
A4: Data | B4: Mês/Ano | C4: Mercado | D4: Produto | E4: Categoria | F4: Qtd. | G4: Unid. | H4: Total Pago | I4: Preço Unit. | J4: Origem | K4: Obs.
A5: 46147 | B5: =TEXT(A5,"mmm/aaaa") -> Iyar/Tuesday | C5: Supermercados Nori | D5: IOGURTE VOVO ANIZIA | E5: Laticinios | F5: 1 | G5: UN | H5: 10.8 | I5: =IFERROR(H5/F5,0) -> 10.8 | J5: Cupom 00091475
A6: 46147 | B6: =TEXT(A6,"mmm/aaaa") -> Iyar/Tuesday | C6: Supermercados Nori | D6: FERMENTADO ITAMBE | E6: Laticinios | F6: 1 | G6: UN | H6: 14.5 | I6: =IFERROR(H6/F6,0) -> 14.5 | J6: Cupom 00091475
A7: 46147 | B7: =TEXT(A7,"mmm/aaaa") -> Iyar/Tuesday | C7: Supermercados Nori | D7: REQUEIJAO VIGOR | E7: Laticinios | F7: 1 | G7: UN | H7: 17.5 | I7: =IFERROR(H7/F7,0) -> 17.5 | J7: Cupom 00091475
A8: 46147 | B8: =TEXT(A8,"mmm/aaaa") -> Iyar/Tuesday | C8: Supermercados Nori | D8: MARGARINA DELICIA | E8: Laticinios | F8: 1 | G8: UN | H8: 6.25 | I8: =IFERROR(H8/F8,0) -> 6.25 | J8: Cupom 00091475
A9: 46147 | B9: =TEXT(A9,"mmm/aaaa") -> Iyar/Tuesday | C9: Supermercados Nori | D9: LEITE SERRALAT PADRAO | E9: Laticinios | F9: 1 | G9: UN | H9: 6.65 | I9: =IFERROR(H9/F9,0) -> 6.65 | J9: Cupom 00091475
A10: 46147 | B10: =TEXT(A10,"mmm/aaaa") -> Iyar/Tuesday | C10: Supermercados Nori | D10: CAFE 3 CORACOES | E10: Mercearia | F10: 1 | G10: UN | H10: 23 | I10: =IFERROR(H10/F10,0) -> 23 | J10: Cupom 00091475
A11: 46147 | B11: =TEXT(A11,"mmm/aaaa") -> Iyar/Tuesday | C11: Supermercados Nori | D11: AMENDOIM DELTA | E11: Mercearia | F11: 1 | G11: UN | H11: 10.99 | I11: =IFERROR(H11/F11,0) -> 10.99 | J11: Cupom 00091475
A12: 46147 | B12: =TEXT(A12,"mmm/aaaa") -> Iyar/Tuesday | C12: Supermercados Nori | D12: ACUCAR CRISTAL | E12: Mercearia | F12: 1 | G12: UN | H12: 5.75 | I12: =IFERROR(H12/F12,0) -> 5.75 | J12: Cupom 00091475
A13: 46147 | B13: =TEXT(A13,"mmm/aaaa") -> Iyar/Tuesday | C13: Supermercados Nori | D13: SAL LEBRE MARINHO | E13: Mercearia | F13: 1 | G13: UN | H13: 2.49 | I13: =IFERROR(H13/F13,0) -> 2.49 | J13: Cupom 00091475
A14: 46147 | B14: =TEXT(A14,"mmm/aaaa") -> Iyar/Tuesday | C14: Supermercados Nori | D14: BISCOITO TUCS | E14: Mercearia | F14: 3 | G14: UN | H14: 5.4 | I14: =IFERROR(H14/F14,0) -> 1.8 | J14: Cupom 00091475
A15: 46147 | B15: =TEXT(A15,"mmm/aaaa") -> Iyar/Tuesday | C15: Supermercados Nori | D15: BISCOITO NESFIT | E15: Mercearia | F15: 1 | G15: UN | H15: 3.7 | I15: =IFERROR(H15/F15,0) -> 3.7 | J15: Cupom 00091475
A16: 46147 | B16: =TEXT(A16,"mmm/aaaa") -> Iyar/Tuesday | C16: Supermercados Nori | D16: BISCOITO NESFIT | E16: Mercearia | F16: 3 | G16: UN | H16: 11.1 | I16: =IFERROR(H16/F16,0) -> 3.7 | J16: Cupom 00091475
... A37: 46147 | B37: =TEXT(A37,"mmm/aaaa") -> Iyar/Tuesday | C37: Supermercados Nori | D37: SABAO PO SURF | E37: Limpeza | F37: 1 | G37: UN | H37: 16.6 | I37: =IFERROR(H37/F37,0) -> 16.6 | J37: Cupom 00091475
A38: 46148 | B38: =TEXT(A38,"mmm/aaaa") -> Iyar/Wednesday | C38: Varejao Monteverde | D38: BERINJELA | E38: Hortifruti | F38: 0.574 | G38: KG | H38: 2 | I38: =IFERROR(H38/F38,0) -> 3.4843206 | J38: NFC-e Varejao Monteverde 2410 | K38: Item da nota do Varejao Monteverde
A39: 46148 | B39: =TEXT(A39,"mmm/aaaa") -> Iyar/Wednesday | C39: Varejao Monteverde | D39: BANANA NANICA | E39: Hortifruti | F39: 1.504 | G39: KG | H39: 7.49 | I39: =IFERROR(H39/F39,0) -> 4.9800532 | J39: NFC-e Varejao Monteverde 2410 | K39: Item da nota do Varejao Monteverde
A40: 46148 | B40: =TEXT(A40,"mmm/aaaa") -> Iyar/Wednesday | C40: Varejao Monteverde | D40: MACA GALA | E40: Hortifruti | F40: 0.702 | G40: KG | H40: 8.2 | I40: =IFERROR(H40/F40,0) -> 11.680912 | J40: NFC-e Varejao Monteverde 2410 | K40: Item da nota do Varejao Monteverde
A41: 46144 | B41: =TEXT(A41,"mmm/aaaa") -> Iyar/Shabbat | C41: Crystal | D41: BISCOITO SIMPLES KG | E41: Padaria | F41: 0.085935132 | G41: KG | H41: 5.67 | I41: =IFERROR(H41/F41,0) -> 65.98 | J41: NFC-e Crystal 000052920 | K41: Quantidade calculada pelo total/preco unitario da nota: 5,67 / 65,98 = 0,0859 kg.
A42: 46144 | B42: =TEXT(A42,"mmm/aaaa") -> Iyar/Shabbat | C42: Crystal | D42: BOLACHA TRANCADINHA DE CANELA 250G | E42: Mercearia | F42: 1 | G42: UN | H42: 11.98 | I42: =IFERROR(H42/F42,0) -> 11.98 | J42: NFC-e Crystal 000052920 | K42: Item da nota Crystal
A43: 46144 | B43: =TEXT(A43,"mmm/aaaa") -> Iyar/Shabbat | C43: Crystal | D43: PAO FRANCES KG | E43: Padaria | F43: 0.59 | G43: KG | H43: 10.02 | I43: =IFERROR(H43/F43,0) -> 16.983051 | J43: NFC-e Crystal 000052920 | K43: Item da nota Crystal
A44: 46151 | B44: =TEXT(A44,"mmm/aaaa") -> Iyar/Shabbat | C44: Supermercado Canesin | D44: LIMAO KG | E44: Hortifruti | F44: 0.645 | G44: KG | H44: 1.28 | I44: =IFERROR(H44/F44,0) -> 1.9844961 | J44: NFC-e Canesin 000038274 | K44: Item da nota Canesin (Brodowski-SP)
A45: 46151 | B45: =TEXT(A45,"mmm/aaaa") -> Iyar/Shabbat | C45: Supermercado Canesin | D45: GRAO DE BICO KODILAR | E45: Mercearia | F45: 1 | G45: UN | H45: 14.9 | I45: =IFERROR(H45/F45,0) -> 14.9 | J45: NFC-e Canesin 000038274 | K45: Item da nota Canesin (Brodowski-SP)
A46: 46152 | B46: =TEXT(A46,"mmm/aaaa") -> Iyar/Sunday | C46: Casa de Carnes Barao da Carne | D46: COSTELINHA TEMP SUIN | E46: Carnes | F46: 1.04 | G46: KG | H46: 34.22 | I46: =IFERROR(H46/F46,0) -> 32.903846 | J46: Orcamento Pedido 083825 | K46: Casa de Carnes Barao da Carne (Brodowski-SP) - Sem Valor Fiscal
A47: 46152 | B47: =TEXT(A47,"mmm/aaaa") -> Iyar/Sunday | C47: Casa de Carnes Barao da Carne | D47: PERNIL CARNEIRO TEMP | E47: Carnes | F47: 0.554 | G47: KG | H47: 44.26 | I47: =IFERROR(H47/F47,0) -> 79.891697 | J47: Orcamento Pedido 083825 | K47: Casa de Carnes Barao da Carne (Brodowski-SP) - Sem Valor Fiscal
A48: 46152 | B48: =TEXT(A48,"mmm/aaaa") -> Iyar/Sunday | C48: Varejao Monteverde | D48: BANANA NANICA | E48: Hortifruti | F48: 1.312 | G48: KG | H48: 6.53 | I48: =IFERROR(H48/F48,0) -> 4.9771341 | J48: NFC-e Varejao Monteverde 8933 | K48: Item da nota do Varejao Monteverde - 10/05/2026
A49: 46152 | B49: =TEXT(A49,"mmm/aaaa") -> Iyar/Sunday | C49: Varejao Monteverde | D49: OVOS SEMI CAIPIRA | E49: Mercearia | F49: 6 | G49: UN | H49: 7.2 | I49: =IFERROR(H49/F49,0) -> 1.2 | J49: NFC-e Varejao Monteverde 8933 | K49: Item da nota do Varejao Monteverde - 10/05/2026
... A63: 46158 | B63: =TEXT(A63,"mmm/aaaa") -> Iyar/Shabbat | C63: Varejao Nova Brasil | D63: Limão Taiti | E63: Hortifruti | F63: 0.635 | G63: KG | H63: 5.07 | I63: =IFERROR(H63/F63,0) -> 7.984252 | J63: Cupom Não Fiscal | K63: R$ 7,99/kg
A64: 46157 | B64: =TEXT(A64,"mmm/aaaa") -> Iyar/Friday | C64: Supermercados Nori | D64: Fubá Zei | E64: Mercearia | F64: 1 | G64: UN | H64: 3.6 | I64: =IFERROR(H64/F64,0) -> 3.6 | J64: NFC-e 65290
A65: 46157 | B65: =TEXT(A65,"mmm/aaaa") -> Iyar/Friday | C65: Supermercados Nori | D65: Feijão Preto Empório | E65: Mercearia | F65: 1 | G65: UN | H65: 7.99 | I65: =IFERROR(H65/F65,0) -> 7.99 | J65: NFC-e 65290
A66: 46157 | B66: =TEXT(A66,"mmm/aaaa") -> Iyar/Friday | C66: Supermercados Nori | D66: Café TM Padrão | E66: Mercearia | F66: 1 | G66: UN | H66: 21 | I66: =IFERROR(H66/F66,0) -> 21 | J66: NFC-e 65290
A67: 46157 | B67: =TEXT(A67,"mmm/aaaa") -> Iyar/Friday | C67: Supermercados Nori | D67: Lentilha Kinino | E67: Mercearia | F67: 1 | G67: UN | H67: 10.7 | I67: =IFERROR(H67/F67,0) -> 10.7 | J67: NFC-e 65290
A68: 46157 | B68: =TEXT(A68,"mmm/aaaa") -> Iyar/Friday | C68: Supermercados Nori | D68: Milho Pipoca Kinino | E68: Mercearia | F68: 1 | G68: UN | H68: 3.89 | I68: =IFERROR(H68/F68,0) -> 3.89 | J68: NFC-e 65290
A69: 46157 | B69: =TEXT(A69,"mmm/aaaa") -> Iyar/Friday | C69: Supermercados Nori | D69: Salgadinhos Balatore | E69: Mercearia | F69: 1 | G69: UN | H69: 9.2 | I69: =IFERROR(H69/F69,0) -> 9.2 | J69: NFC-e 65290
A70: 46157 | B70: =TEXT(A70,"mmm/aaaa") -> Iyar/Friday | C70: Supermercados Nori | D70: Grão de Bico | E70: Mercearia | F70: 1 | G70: UN | H70: 11.99 | I70: =IFERROR(H70/F70,0) -> 11.99 | J70: NFC-e 65290
A71: 46157 | B71: =TEXT(A71,"mmm/aaaa") -> Iyar/Friday | C71: Supermercados Nori | D71: Macarrão Galo | E71: Mercearia | F71: 1 | G71: UN | H71: 2.95 | I71: =IFERROR(H71/F71,0) -> 2.95 | J71: NFC-e 65290
A72: 46157 | B72: =TEXT(A72,"mmm/aaaa") -> Iyar/Friday | C72: Supermercados Nori | D72: Chá Condinew Hibisco | E72: Mercearia | F72: 1 | G72: UN | H72: 2.75 | I72: =IFERROR(H72/F72,0) -> 2.75 | J72: NFC-e 65290
A73: 46157 | B73: =TEXT(A73,"mmm/aaaa") -> Iyar/Friday | C73: Supermercados Nori | D73: Erva Doce Condinew | E73: Mercearia | F73: 1 | G73: UN | H73: 3.85 | I73: =IFERROR(H73/F73,0) -> 3.85 | J73: NFC-e 65290
A74: 46157 | B74: =TEXT(A74,"mmm/aaaa") -> Iyar/Friday | C74: Supermercados Nori | D74: Lemon Pepper | E74: Mercearia | F74: 1 | G74: UN | H74: 3.85 | I74: =IFERROR(H74/F74,0) -> 3.85 | J74: NFC-e 65290
...

Sheet Comparador
Q1: Todas
B2: COMPARADOR DE PREÇOS | Q2: Açougue
B3: Onde cada produto já saiu mais barato e mais caro — e quanto dá para economizar comprando no lugar certo. Tudo em fórmula: atualiza sozinho pela aba Compras. | Q3: Bebidas
Q4: Café
B5: CATEGORIA (filtro ▾) | C5: PRODUTOS COMPARADOS | F5: ECONOMIA POSSÍVEL | H5: PRODUTOS C/ ECONOMIA | J5: PREÇO MÍNIMO MÉDIO | Q5: Carnes
B6: Todas | C6: =IF($B$6="Todas",COUNTA($B$25:$B$218),COUNTIF($D$25:$D$218,$B$6)) -> 194 | F6: =IF($B$6="Todas",SUM($K$25:$K$218),SUMIF($D$25:$D$218,$B$6,$K$25:$K$218)) -> 92.625378 | H6: =IF($B$6="Todas",COUNTIFS($K$25:$K$218,">0"),COUNTIFS($D$25:$D$218,$B$6,$K$25:$K$218,">0")) -> 57 | J6: =IFERROR(IF($B$6="Todas",AVERAGE($E$25:$E$218),AVERAGEIF($D$25:$D$218,$B$6,$E$25:$E$218)),0) -> 12.431325 | Q6: Frios
Q7: Frutas
B8: TOP 10 OPORTUNIDADES DE ECONOMIA | Q8: Higiene
B9: Maiores diferenças por unidade entre o preço mais caro e o mais barato já pagos — comece a economizar por aqui. A lista muda conforme a categoria escolhida acima. | Q9: Hortifruti
B10: Produto | C10: Categoria | E10: Menor R$ | F10: Onde + quando (mais barato) | H10: Última R$ | I10: Economia / un. | Q10: Laticinios
B11: =IFERROR(INDEX($B$25:$B$218,MATCH(LARGE($P$25:$P$218,1),$P$25:$P$218,0)),"") -> CAFE TM 3 CORACOES | C11: =IFERROR(INDEX($D$25:$D$218,MATCH(LARGE($P$25:$P$218,1),$P$25:$P$218,0)),"") -> Mercearia | E11: =IFERROR(INDEX($E$25:$E$218,MATCH(LARGE($P$25:$P$218,1),$P$25:$P$218,0)),"") -> 23 | F11: =IFERROR(INDEX($F$25:$F$218,MATCH(LARGE($P$25:$P$218,1),$P$25:$P$218,0))&" · "&TEXT(DAY(INDEX($G$25:$G$218,MATCH(LARGE($P$25:$P$218,1),$P$25:$P$218,0))),"00")&"/"&TEXT(MONTH(INDEX($G$25:$G$218,MATCH(LARGE($P$25:$P$218,1),$P$25:$P$218,0))),"00")&"/"&TEXT(MOD(YEAR(INDEX($G$25:$G$218,MATCH(LARGE($P$25:$P$218,1),$P$25:$P$218,0))),100),"00"),"") -> Supermercados Nori · 20/06/26 | H11: =IFERROR(INDEX($M$25:$M$218,MATCH(LARGE($P$25:$P$218,1),$P$25:$P$218,0)),"") -> 23 | I11: =IFERROR(INDEX($K$25:$K$218,MATCH(LARGE($P$25:$P$218,1),$P$25:$P$218,0)),"") -> 8.7 | Q11: Laticínios
B12: =IFERROR(INDEX($B$25:$B$218,MATCH(LARGE($P$25:$P$218,2),$P$25:$P$218,0)),"") -> Pão Francês | C12: =IFERROR(INDEX($D$25:$D$218,MATCH(LARGE($P$25:$P$218,2),$P$25:$P$218,0)),"") -> Padaria | E12: =IFERROR(INDEX($E$25:$E$218,MATCH(LARGE($P$25:$P$218,2),$P$25:$P$218,0)),"") -> 14.991597 | F12: =IFERROR(INDEX($F$25:$F$218,MATCH(LARGE($P$25:$P$218,2),$P$25:$P$218,0))&" · "&TEXT(DAY(INDEX($G$25:$G$218,MATCH(LARGE($P$25:$P$218,2),$P$25:$P$218,0))),"00")&"/"&TEXT(MONTH(INDEX($G$25:$G$218,MATCH(LARGE($P$25:$P$218,2),$P$25:$P$218,0))),"00")&"/"&TEXT(MOD(YEAR(INDEX($G$25:$G$218,MATCH(LARGE($P$25:$P$218,2),$P$25:$P$218,0))),100),"00"),"") -> André · 27/05/26 | H12: =IFERROR(INDEX($M$25:$M$218,MATCH(LARGE($P$25:$P$218,2),$P$25:$P$218,0)),"") -> 14.991597 | I12: =IFERROR(INDEX($K$25:$K$218,MATCH(LARGE($P$25:$P$218,2),$P$25:$P$218,0)),"") -> 7.9134313 | Q12: Limpeza
B13: =IFERROR(INDEX($B$25:$B$218,MATCH(LARGE($P$25:$P$218,3),$P$25:$P$218,0)),"") -> LIMAO KG | C13: =IFERROR(INDEX($D$25:$D$218,MATCH(LARGE($P$25:$P$218,3),$P$25:$P$218,0)),"") -> Hortifruti | E13: =IFERROR(INDEX($E$25:$E$218,MATCH(LARGE($P$25:$P$218,3),$P$25:$P$218,0)),"") -> 1.9844961 | F13: =IFERROR(INDEX($F$25:$F$218,MATCH(LARGE($P$25:$P$218,3),$P$25:$P$218,0))&" · "&TEXT(DAY(INDEX($G$25:$G$218,MATCH(LARGE($P$25:$P$218,3),$P$25:$P$218,0))),"00")&"/"&TEXT(MONTH(INDEX($G$25:$G$218,MATCH(LARGE($P$25:$P$218,3),$P$25:$P$218,0))),"00")&"/"&TEXT(MOD(YEAR(INDEX($G$25:$G$218,MATCH(LARGE($P$25:$P$218,3),$P$25:$P$218,0))),100),"00"),"") -> Supermercado Canesin · 09/05/26 | H13: =IFERROR(INDEX($M$25:$M$218,MATCH(LARGE($P$25:$P$218,3),$P$25:$P$218,0)),"") -> 9.8987342 | I13: =IFERROR(INDEX($K$25:$K$218,MATCH(LARGE($P$25:$P$218,3),$P$25:$P$218,0)),"") -> 7.9142381 | Q13: Mercearia
B14: =IFERROR(INDEX($B$25:$B$218,MATCH(LARGE($P$25:$P$218,4),$P$25:$P$218,0)),"") -> Ketchup | C14: =IFERROR(INDEX($D$25:$D$218,MATCH(LARGE($P$25:$P$218,4),$P$25:$P$218,0)),"") -> Mercearia | E14: =IFERROR(INDEX($E$25:$E$218,MATCH(LARGE($P$25:$P$218,4),$P$25:$P$218,0)),"") -> 5.9 | F14: =IFERROR(INDEX($F$25:$F$218,MATCH(LARGE($P$25:$P$218,4),$P$25:$P$218,0))&" · "&TEXT(DAY(INDEX($G$25:$G$218,MATCH(LARGE($P$25:$P$218,4),$P$25:$P$218,0))),"00")&"/"&TEXT(MONTH(INDEX($G$25:$G$218,MATCH(LARGE($P$25:$P$218,4),$P$25:$P$218,0))),"00")&"/"&TEXT(MOD(YEAR(INDEX($G$25:$G$218,MATCH(LARGE($P$25:$P$218,4),$P$25:$P$218,0))),100),"00"),"") -> Supermercados Nori · 31/05/26 | H14: =IFERROR(INDEX($M$25:$M$218,MATCH(LARGE($P$25:$P$218,4),$P$25:$P$218,0)),"") -> 5.9 | I14: =IFERROR(INDEX($K$25:$K$218,MATCH(LARGE($P$25:$P$218,4),$P$25:$P$218,0)),"") -> 6 | Q14: Padaria
B15: =IFERROR(INDEX($B$25:$B$218,MATCH(LARGE($P$25:$P$218,5),$P$25:$P$218,0)),"") -> KETCHUP | C15: =IFERROR(INDEX($D$25:$D$218,MATCH(LARGE($P$25:$P$218,5),$P$25:$P$218,0)),"") -> Mercearia | E15: =IFERROR(INDEX($E$25:$E$218,MATCH(LARGE($P$25:$P$218,5),$P$25:$P$218,0)),"") -> 5.9 | F15: =IFERROR(INDEX($F$25:$F$218,MATCH(LARGE($P$25:$P$218,5),$P$25:$P$218,0))&" · "&TEXT(DAY(INDEX($G$25:$G$218,MATCH(LARGE($P$25:$P$218,5),$P$25:$P$218,0))),"00")&"/"&TEXT(MONTH(INDEX($G$25:$G$218,MATCH(LARGE($P$25:$P$218,5),$P$25:$P$218,0))),"00")&"/"&TEXT(MOD(YEAR(INDEX($G$25:$G$218,MATCH(LARGE($P$25:$P$218,5),$P$25:$P$218,0))),100),"00"),"") -> Supermercados Nori · 31/05/26 | H15: =IFERROR(INDEX($M$25:$M$218,MATCH(LARGE($P$25:$P$218,5),$P$25:$P$218,0)),"") -> 5.9 | I15: =IFERROR(INDEX($K$25:$K$218,MATCH(LARGE($P$25:$P$218,5),$P$25:$P$218,0)),"") -> 6 | Q15: Pet
B16: =IFERROR(INDEX($B$25:$B$218,MATCH(LARGE($P$25:$P$218,6),$P$25:$P$218,0)),"") -> BATATA EXTRA | C16: =IFERROR(INDEX($D$25:$D$218,MATCH(LARGE($P$25:$P$218,6),$P$25:$P$218,0)),"") -> Hortifruti | E16: =IFERROR(INDEX($E$25:$E$218,MATCH(LARGE($P$25:$P$218,6),$P$25:$P$218,0)),"") -> 5.2827381 | F16: =IFERROR(INDEX($F$25:$F$218,MATCH(LARGE($P$25:$P$218,6),$P$25:$P$218,0))&" · "&TEXT(DAY(INDEX($G$25:$G$218,MATCH(LARGE($P$25:$P$218,6),$P$25:$P$218,0))),"00")&"/"&TEXT(MONTH(INDEX($G$25:$G$218,MATCH(LARGE($P$25:$P$218,6),$P$25:$P$218,0))),"00")&"/"&TEXT(MOD(YEAR(INDEX($G$25:$G$218,MATCH(LARGE($P$25:$P$218,6),$P$25:$P$218,0))),100),"00"),"") -> Varejao Monteverde · 17/07/26 | H16: =IFERROR(INDEX($M$25:$M$218,MATCH(LARGE($P$25:$P$218,6),$P$25:$P$218,0)),"") -> 5.2830189 | I16: =IFERROR(INDEX($K$25:$K$218,MATCH(LARGE($P$25:$P$218,6),$P$25:$P$218,0)),"") -> 5.6965613 | Q16: Rotisseria
B17: =IFERROR(INDEX($B$25:$B$218,MATCH(LARGE($P$25:$P$218,7),$P$25:$P$218,0)),"") -> Batata Palito | C17: =IFERROR(INDEX($D$25:$D$218,MATCH(LARGE($P$25:$P$218,7),$P$25:$P$218,0)),"") -> Mercearia | E17: =IFERROR(INDEX($E$25:$E$218,MATCH(LARGE($P$25:$P$218,7),$P$25:$P$218,0)),"") -> 15.79 | F17: =IFERROR(INDEX($F$25:$F$218,MATCH(LARGE($P$25:$P$218,7),$P$25:$P$218,0))&" · "&TEXT(DAY(INDEX($G$25:$G$218,MATCH(LARGE($P$25:$P$218,7),$P$25:$P$218,0))),"00")&"/"&TEXT(MONTH(INDEX($G$25:$G$218,MATCH(LARGE($P$25:$P$218,7),$P$25:$P$218,0))),"00")&"/"&TEXT(MOD(YEAR(INDEX($G$25:$G$218,MATCH(LARGE($P$25:$P$218,7),$P$25:$P$218,0))),100),"00"),"") -> Supermercados Nori · 20/06/26 | H17: =IFERROR(INDEX($M$25:$M$218,MATCH(LARGE($P$25:$P$218,7),$P$25:$P$218,0)),"") -> 15.79 | I17: =IFERROR(INDEX($K$25:$K$218,MATCH(LARGE($P$25:$P$218,7),$P$25:$P$218,0)),"") -> 5.21 | Q17: Saúde
B18: =IFERROR(INDEX($B$25:$B$218,MATCH(LARGE($P$25:$P$218,8),$P$25:$P$218,0)),"") -> LIMAO THAITI | C18: =IFERROR(INDEX($D$25:$D$218,MATCH(LARGE($P$25:$P$218,8),$P$25:$P$218,0)),"") -> Hortifruti | E18: =IFERROR(INDEX($E$25:$E$218,MATCH(LARGE($P$25:$P$218,8),$P$25:$P$218,0)),"") -> 2.6825843 | F18: =IFERROR(INDEX($F$25:$F$218,MATCH(LARGE($P$25:$P$218,8),$P$25:$P$218,0))&" · "&TEXT(DAY(INDEX($G$25:$G$218,MATCH(LARGE($P$25:$P$218,8),$P$25:$P$218,0))),"00")&"/"&TEXT(MONTH(INDEX($G$25:$G$218,MATCH(LARGE($P$25:$P$218,8),$P$25:$P$218,0))),"00")&"/"&TEXT(MOD(YEAR(INDEX($G$25:$G$218,MATCH(LARGE($P$25:$P$218,8),$P$25:$P$218,0))),100),"00"),"") -> Varejao Monteverde · 31/05/26 | H18: =IFERROR(INDEX($M$25:$M$218,MATCH(LARGE($P$25:$P$218,8),$P$25:$P$218,0)),"") -> 7.5051546 | I18: =IFERROR(INDEX($K$25:$K$218,MATCH(LARGE($P$25:$P$218,8),$P$25:$P$218,0)),"") -> 4.8225704
B19: =IFERROR(INDEX($B$25:$B$218,MATCH(LARGE($P$25:$P$218,9),$P$25:$P$218,0)),"") -> PAO FRANCES (FILAO) | C19: =IFERROR(INDEX($D$25:$D$218,MATCH(LARGE($P$25:$P$218,9),$P$25:$P$218,0)),"") -> Padaria | E19: =IFERROR(INDEX($E$25:$E$218,MATCH(LARGE($P$25:$P$218,9),$P$25:$P$218,0)),"") -> 14.891304 | F19: =IFERROR(INDEX($F$25:$F$218,MATCH(LARGE($P$25:$P$218,9),$P$25:$P$218,0))&" · "&TEXT(DAY(INDEX($G$25:$G$218,MATCH(LARGE($P$25:$P$218,9),$P$25:$P$218,0))),"00")&"/"&TEXT(MONTH(INDEX($G$25:$G$218,MATCH(LARGE($P$25:$P$218,9),$P$25:$P$218,0))),"00")&"/"&TEXT(MOD(YEAR(INDEX($G$25:$G$218,MATCH(LARGE($P$25:$P$218,9),$P$25:$P$218,0))),100),"00"),"") -> Supermercados Nori · 31/05/26 | H19: =IFERROR(INDEX($M$25:$M$218,MATCH(LARGE($P$25:$P$218,9),$P$25:$P$218,0)),"") -> 14.897959 | I19: =IFERROR(INDEX($K$25:$K$218,MATCH(LARGE($P$25:$P$218,9),$P$25:$P$218,0)),"") -> 3.0161031
B20: =IFERROR(INDEX($B$25:$B$218,MATCH(LARGE($P$25:$P$218,10),$P$25:$P$218,0)),"") -> BANANA NANICA | C20: =IFERROR(INDEX($D$25:$D$218,MATCH(LARGE($P$25:$P$218,10),$P$25:$P$218,0)),"") -> Hortifruti | E20: =IFERROR(INDEX($E$25:$E$218,MATCH(LARGE($P$25:$P$218,10),$P$25:$P$218,0)),"") -> 3.9827586 | F20: =IFERROR(INDEX($F$25:$F$218,MATCH(LARGE($P$25:$P$218,10),$P$25:$P$218,0))&" · "&TEXT(DAY(INDEX($G$25:$G$218,MATCH(LARGE($P$25:$P$218,10),$P$25:$P$218,0))),"00")&"/"&TEXT(MONTH(INDEX($G$25:$G$218,MATCH(LARGE($P$25:$P$218,10),$P$25:$P$218,0))),"00")&"/"&TEXT(MOD(YEAR(INDEX($G$25:$G$218,MATCH(LARGE($P$25:$P$218,10),$P$25:$P$218,0))),100),"00"),"") -> Supermercado Canesin · 04/06/26 | H20: =IFERROR(INDEX($M$25:$M$218,MATCH(LARGE($P$25:$P$218,10),$P$25:$P$218,0)),"") -> 6.9877883 | I20: =IFERROR(INDEX($K$25:$K$218,MATCH(LARGE($P$25:$P$218,10),$P$25:$P$218,0)),"") -> 3.0061148
B22: COMPARATIVO COMPLETO — PRODUTO A PRODUTO
B23: Menor e maior preço já pagos, onde foi, e a última compra. Barra azul = tamanho da economia possível. Última R$ verde = você pagou o mínimo · vermelho = pagou acima do mínimo.
B24: Produto | C24: Unid. | D24: Categoria | E24: Menor R$ | F24: Mercado (+ barato) | G24: Data | H24: Maior R$ | I24: Mercado (+ caro) | J24: Data | K24: Economia R$ | L24: Economia % | M24: Última R$ | N24: Última compra (onde · quando)
B25: Linguiça Fina | C25: KG | D25: Açougue | E25: =IFERROR(_xlfn.MINIFS(tblCompras[Preço Unit.],tblCompras[Produto],$B25,tblCompras[Unid.],$C25),"") -> 28.90625 | F25: =IFERROR(LOOKUP(2,1/((tblCompras[Produto]=$B25)*(tblCompras[Unid.]=$C25)*(tblCompras[Preço Unit.]=$E25)),tblCompras[Mercado]),"") -> Supermercados Nori | G25: =IFERROR(LOOKUP(2,1/((tblCompras[Produto]=$B25)*(tblCompras[Unid.]=$C25)*(tblCompras[Preço Unit.]=$E25)),tblCompras[Data]),"") -> 46146 | H25: =IFERROR(_xlfn.MAXIFS(tblCompras[Preço Unit.],tblCompras[Produto],$B25,tblCompras[Unid.],$C25),"") -> 28.90625 | I25: =IFERROR(LOOKUP(2,1/((tblCompras[Produto]=$B25)*(tblCompras[Unid.]=$C25)*(tblCompras[Preço Unit.]=$H25)),tblCompras[Mercado]),"") -> Supermercados Nori | J25: =IFERROR(LOOKUP(2,1/((tblCompras[Produto]=$B25)*(tblCompras[Unid.]=$C25)*(tblCompras[Preço Unit.]=$H25)),tblCompras[Data]),"") -> 46146 | K25: =IF(OR($E25="",$H25=""),"",MAX(0,$H25-$E25)) -> 0 | L25: =IF(OR($E25="",$H25="",$E25=0),"",($H25-$E25)/$E25) -> 0 | M25: =IFERROR(LOOKUP(2,1/((tblCompras[Produto]=$B25)*(tblCompras[Unid.]=$C25)*(tblCompras[Data]=_xlfn.MAXIFS(tblCompras[Data],tblCompras[Produto],$B25,tblCompras[Unid.],$C25))),tblCompras[Preço Unit.]),"") -> 28.90625 | N25: =IFERROR(LOOKUP(2,1/((tblCompras[Produto]=$B25)*(tblCompras[Unid.]=$C25)*(tblCompras[Data]=_xlfn.MAXIFS(tblCompras[Data],tblCompras[Produto],$B25,tblCompras[Unid.],$C25))),tblCompras[Mercado])&" · "&TEXT(DAY(_xlfn.MAXIFS(tblCompras[Data],tblCompras[Produto],$B25,tblCompras[Unid.],$C25)),"00")&"/"&TEXT(MONTH(_xlfn.MAXIFS(tblCompras[Data],tblCompras[Produto],$B25,tblCompras[Unid.],$C25)),"00")&"/"&TEXT(MOD(YEAR(_xlfn.MAXIFS(tblCompras[Data],tblCompras[Produto],$B25,tblCompras[Unid.],$C25)),100),"00"),"") -> Supermercados Nori · 04/05/26 | P25: =IF(AND(ISNUMBER($K25),$K25>0,OR($B$6="Todas",$D25=$B$6)),$K25+ROW()/100000,"")
B26: AGUA MINERAL CRISTAL | C26: UN | D26: Bebidas | E26: =IFERROR(_xlfn.MINIFS(tblCompras[Preço Unit.],tblCompras[Produto],$B26,tblCompras[Unid.],$C26),"") -> 1.29 | F26: =IFERROR(LOOKUP(2,1/((tblCompras[Produto]=$B26)*(tblCompras[Unid.]=$C26)*(tblCompras[Preço Unit.]=$E26)),tblCompras[Mercado]),"") -> Supermercados Nori | G26: =IFERROR(LOOKUP(2,1/((tblCompras[Produto]=$B26)*(tblCompras[Unid.]=$C26)*(tblCompras[Preço Unit.]=$E26)),tblCompras[Data]),"") -> 46243 | H26: =IFERROR(_xlfn.MAXIFS(tblCompras[Preço Unit.],tblCompras[Produto],$B26,tblCompras[Unid.],$C26),"") -> 1.65 | I26: =IFERROR(LOOKUP(2,1/((tblCompras[Produto]=$B26)*(tblCompras[Unid.]=$C26)*(tblCompras[Preço Unit.]=$H26)),tblCompras[Mercado]),"") -> Supermercados Nori | J26: =IFERROR(LOOKUP(2,1/((tblCompras[Produto]=$B26)*(tblCompras[Unid.]=$C26)*(tblCompras[Preço Unit.]=$H26)),tblCompras[Data]),"") -> 46215 | K26: =IF(OR($E26="",$H26=""),"",MAX(0,$H26-$E26)) -> 0.36 | L26: =IF(OR($E26="",$H26="",$E26=0),"",($H26-$E26)/$E26) -> 0.27906977 | M26: =IFERROR(LOOKUP(2,1/((tblCompras[Produto]=$B26)*(tblCompras[Unid.]=$C26)*(tblCompras[Data]=_xlfn.MAXIFS(tblCompras[Data],tblCompras[Produto],$B26,tblCompras[Unid.],$C26))),tblCompras[Preço Unit.]),"") -> 1.29 | N26: =IFERROR(LOOKUP(2,1/((tblCompras[Produto]=$B26)*(tblCompras[Unid.]=$C26)*(tblCompras[Data]=_xlfn.MAXIFS(tblCompras[Data],tblCompras[Produto],$B26,tblCompras[Unid.],$C26))),tblCompras[Mercado])&" · "&TEXT(DAY(_xlfn.MAXIFS(tblCompras[Data],tblCompras[Produto],$B26,tblCompras[Unid.],$C26)),"00")&"/"&TEXT(MONTH(_xlfn.MAXIFS(tblCompras[Data],tblCompras[Produto],$B26,tblCompras[Unid.],$C26)),"00")&"/"&TEXT(MOD(YEAR(_xlfn.MAXIFS(tblCompras[Data],tblCompras[Produto],$B26,tblCompras[Unid.],$C26)),100),"00"),"") -> Supermercados Nori · 09/08/26 | P26: =IF(AND(ISNUMBER($K26),$K26>0,OR($B$6="Todas",$D26=$B$6)),$K26+ROW()/100000,"") -> 0.36026
B27: AGUA MINERAL LEVE 490ML C/GAS | C27: FC | D27: Bebidas | E27: =IFERROR(_xlfn.MINIFS(tblCompras[Preço Unit.],tblCompras[Produto],$B27,tblCompras[Unid.],$C27),"") -> 2.5 | F27: =IFERROR(LOOKUP(2,1/((tblCompras[Produto]=$B27)*(tblCompras[Unid.]=$C27)*(tblCompras[Preço Unit.]=$E27)),tblCompras[Mercado]),"") -> Real Atacamix | G27: =IFERROR(LOOKUP(2,1/((tblCompras[Produto]=$B27)*(tblCompras[Unid.]=$C27)*(tblCompras[Preço Unit.]=$E27)),tblCompras[Data]),"") -> 46152 | H27: =IFERROR(_xlfn.MAXIFS(tblCompras[Preço Unit.],tblCompras[Produto],$B27,tblCompras[Unid.],$C27),"") -> 2.5 | I27: =IFERROR(LOOKUP(2,1/((tblCompras[Produto]=$B27)*(tblCompras[Unid.]=$C27)*(tblCompras[Preço Unit.]=$H27)),tblCompras[Mercado]),"") -> Real Atacamix | J27: =IFERROR(LOOKUP(2,1/((tblCompras[Produto]=$B27)*(tblCompras[Unid.]=$C27)*(tblCompras[Preço Unit.]=$H27)),tblCompras[Data]),"") -> 46152 | K27: =IF(OR($E27="",$H27=""),"",MAX(0,$H27-$E27)) -> 0 | L27: =IF(OR($E27="",$H27="",$E27=0),"",($H27-$E27)/$E27) -> 0 | M27: =IFERROR(LOOKUP(2,1/((tblCompras[Produto]=$B27)*(tblCompras[Unid.]=$C27)*(tblCompras[Data]=_xlfn.MAXIFS(tblCompras[Data],tblCompras[Produto],$B27,tblCompras[Unid.],$C27))),tblCompras[Preço Unit.]),"") -> 2.5 | N27: =IFERROR(LOOKUP(2,1/((tblCompras[Produto]=$B27)*(tblCompras[Unid.]=$C27)*(tblCompras[Data]=_xlfn.MAXIFS(tblCompras[Data],tblCompras[Produto],$B27,tblCompras[Unid.],$C27))),tblCompras[Mercado])&" · "&TEXT(DAY(_xlfn.MAXIFS(tblCompras[Data],tblCompras[Produto],$B27,tblCompras[Unid.],$C27)),"00")&"/"&TEXT(MONTH(_xlfn.MAXIFS(tblCompras[Data],tblCompras[Produto],$B27,tblCompras[Unid.],$C27)),"00")&"/"&TEXT(MOD(YEAR(_xlfn.MAXIFS(tblCompras[Data],tblCompras[Produto],$B27,tblCompras[Unid.],$C27)),100),"00"),"") -> Real Atacamix · 10/05/26 | P27: =IF(AND(ISNUMBER($K27),$K27>0,OR($B$6="Todas",$D27=$B$6)),$K27+ROW()/100000,"")
B28: Gatorade 350ml | C28: UN | D28: Bebidas | E28: =IFERROR(_xlfn.MINIFS(tblCompras[Preço Unit.],tblCompras[Produto],$B28,tblCompras[Unid.],$C28),"") -> 4.99 | F28: =IFERROR(LOOKUP(2,1/((tblCompras[Produto]=$B28)*(tblCompras[Unid.]=$C28)*(tblCompras[Preço Unit.]=$E28)),tblCompras[Mercado]),"") -> Supermercado Canesin | G28: =IFERROR(LOOKUP(2,1/((tblCompras[Produto]=$B28)*(tblCompras[Unid.]=$C28)*(tblCompras[Preço Unit.]=$E28)),tblCompras[Data]),"") -> 46161 | H28: =IFERROR(_xlfn.MAXIFS(tblCompras[Preço Unit.],tblCompras[Produto],$B28,tblCompras[Unid.],$C28),"") -> 4.99 | I28: =IFERROR(LOOKUP(2,1/((tblCompras[Produto]=$B28)*(tblCompras[Unid.]=$C28)*(tblCompras[Preço Unit.]=$H28)),tblCompras[Mercado]),"") -> Supermercado Canesin | J28: =IFERROR(LOOKUP(2,1/((tblCompras[Produto]=$B28)*(tblCompras[Unid.]=$C28)*(tblCompras[Preço Unit.]=$H28)),tblCompras[Data]),"") -> 46161 | K28: =IF(OR($E28="",$H28=""),"",MAX(0,$H28-$E28)) -> 0 | L28: =IF(OR($E28="",$H28="",$E28=0),"",($H28-$E28)/$E28) -> 0 | M28: =IFERROR(LOOKUP(2,1/((tblCompras[Produto]=$B28)*(tblCompras[Unid.]=$C28)*(tblCompras[Data]=_xlfn.MAXIFS(tblCompras[Data],tblCompras[Produto],$B28,tblCompras[Unid.],$C28))),tblCompras[Preço Unit.]),"") -> 4.99 | N28: =IFERROR(LOOKUP(2,1/((tblCompras[Produto]=$B28)*(tblCompras[Unid.]=$C28)*(tblCompras[Data]=_xlfn.MAXIFS(tblCompras[Data],tblCompras[Produto],$B28,tblCompras[Unid.],$C28))),tblCompras[Mercado])&" · "&TEXT(DAY(_xlfn.MAXIFS(tblCompras[Data],tblCompras[Produto],$B28,tblCompras[Unid.],$C28)),"00")&"/"&TEXT(MONTH(_xlfn.MAXIFS(tblCompras[Data],tblCompras[Produto],$B28,tblCompras[Unid.],$C28)),"00")&"/"&TEXT(MOD(YEAR(_xlfn.MAXIFS(tblCompras[Data],tblCompras[Produto],$B28,tblCompras[Unid.],$C28)),100),"00"),"") -> Supermercado Canesin · 19/05/26 | P28: =IF(AND(ISNUMBER($K28),$K28>0,OR($B$6="Todas",$D28=$B$6)),$K28+ROW()/100000,"")
B29: Gatorade Tangerina 500ml | C29: UN | D29: Bebidas | E29: =IFERROR(_xlfn.MINIFS(tblCompras[Preço Unit.],tblCompras[Produto],$B29,tblCompras[Unid.],$C29),"") -> 6.99 | F29: =IFERROR(LOOKUP(2,1/((tblCompras[Produto]=$B29)*(tblCompras[Unid.]=$C29)*(tblCompras[Preço Unit.]=$E29)),tblCompras[Mercado]),"") -> Canesin | G29: =IFERROR(LOOKUP(2,1/((tblCompras[Produto]=$B29)*(tblCompras[Unid.]=$C29)*(tblCompras[Preço Unit.]=$E29)),tblCompras[Data]),"") -> 46169 | H29: =IFERROR(_xlfn.MAXIFS(tblCompras[Preço Unit.],tblCompras[Produto],$B29,tblCompras[Unid.],$C29),"") -> 6.99 | I29: =IFERROR(LOOKUP(2,1/((tblCompras[Produto]=$B29)*(tblCompras[Unid.]=$C29)*(tblCompras[Preço Unit.]=$H29)),tblCompras[Mercado]),"") -> Canesin | J29: =IFERROR(LOOKUP(2,1/((tblCompras[Produto]=$B29)*(tblCompras[Unid.]=$C29)*(tblCompras[Preço Unit.]=$H29)),tblCompras[Data]),"") -> 46169 | K29: =IF(OR($E29="",$H29=""),"",MAX(0,$H29-$E29)) -> 0 | L29: =IF(OR($E29="",$H29="",$E29=0),"",($H29-$E29)/$E29) -> 0 | M29: =IFERROR(LOOKUP(2,1/((tblCompras[Produto]=$B29)*(tblCompras[Unid.]=$C29)*(tblCompras[Data]=_xlfn.MAXIFS(tblCompras[Data],tblCompras[Produto],$B29,tblCompras[Unid.],$C29))),tblCompras[Preço Unit.]),"") -> 6.99 | N29: =IFERROR(LOOKUP(2,1/((tblCompras[Produto]=$B29)*(tblCompras[Unid.]=$C29)*(tblCompras[Data]=_xlfn.MAXIFS(tblCompras[Data],tblCompras[Produto],$B29,tblCompras[Unid.],$C29))),tblCompras[Mercado])&" · "&TEXT(DAY(_xlfn.MAXIFS(tblCompras[Data],tblCompras[Produto],$B29,tblCompras[Unid.],$C29)),"00")&"/"&TEXT(MONTH(_xlfn.MAXIFS(tblCompras[Data],tblCompras[Produto],$B29,tblCompras[Unid.],$C29)),"00")&"/"&TEXT(MOD(YEAR(_xlfn.MAXIFS(tblCompras[Data],tblCompras[Produto],$B29,tblCompras[Unid.],$C29)),100),"00"),"") -> Canesin · 27/05/26 | P29: =IF(AND(ISNUMBER($K29),$K29>0,OR($B$6="Todas",$D29=$B$6)),$K29+ROW()/100000,"")
B30: Gatorade Uva 500ml | C30: UN | D30: Bebidas | E30: =IFERROR(_xlfn.MINIFS(tblCompras[Preço Unit.],tblCompras[Produto],$B30,tblCompras[Unid.],$C30),"") -> 6.99 | F30: =IFERROR(LOOKUP(2,1/((tblCompras[Produto]=$B30)*(tblCompras[Unid.]=$C30)*(tblCompras[Preço Unit.]=$E30)),tblCompras[Mercado]),"") -> Canesin | G30: =IFERROR(LOOKUP(2,1/((tblCompras[Produto]=$B30)*(tblCompras[Unid.]=$C30)*(tblCompras[Preço Unit.]=$E30)),tblCompras[Data]),"") -> 46168 | H30: =IFERROR(_xlfn.MAXIFS(tblCompras[Preço Unit.],tblCompras[Produto],$B30,tblCompras[Unid.],$C30),"") -> 6.99 | I30: =IFERROR(LOOKUP(2,1/((tblCompras[Produto]=$B30)*(tblCompras[Unid.]=$C30)*(tblCompras[Preço Unit.]=$H30)),tblCompras[Mercado]),"") -> Canesin | J30: =IFERROR(LOOKUP(2,1/((tblCompras[Produto]=$B30)*(tblCompras[Unid.]=$C30)*(tblCompras[Preço Unit.]=$H30)),tblCompras[Data]),"") -> 46168 | K30: =IF(OR($E30="",$H30=""),"",MAX(0,$H30-$E30)) -> 0 | L30: =IF(OR($E30="",$H30="",$E30=0),"",($H30-$E30)/$E30) -> 0 | M30: =IFERROR(LOOKUP(2,1/((tblCompras[Produto]=$B30)*(tblCompras[Unid.]=$C30)*(tblCompras[Data]=_xlfn.MAXIFS(tblCompras[Data],tblCompras[Produto],$B30,tblCompras[Unid.],$C30))),tblCompras[Preço Unit.]),"") -> 6.99 | N30: =IFERROR(LOOKUP(2,1/((tblCompras[Produto]=$B30)*(tblCompras[Unid.]=$C30)*(tblCompras[Data]=_xlfn.MAXIFS(tblCompras[Data],tblCompras[Produto],$B30,tblCompras[Unid.],$C30))),tblCompras[Mercado])&" · "&TEXT(DAY(_xlfn.MAXIFS(tblCompras[Data],tblCompras[Produto],$B30,tblCompras[Unid.],$C30)),"00")&"/"&TEXT(MONTH(_xlfn.MAXIFS(tblCompras[Data],tblCompras[Produto],$B30,tblCompras[Unid.],$C30)),"00")&"/"&TEXT(MOD(YEAR(_xlfn.MAXIFS(tblCompras[Data],tblCompras[Produto],$B30,tblCompras[Unid.],$C30)),100),"00"),"") -> Canesin · 26/05/26 | P30: =IF(AND(ISNUMBER($K30),$K30>0,OR($B$6="Todas",$D30=$B$6)),$K30+ROW()/100000,"")
B31: PEPSI 2L PET | C31: UN | D31: Bebidas | E31: =IFERROR(_xlfn.MINIFS(tblCompras[Preço Unit.],tblCompras[Produto],$B31,tblCompras[Unid.],$C31),"") -> 10.2 | F31: =IFERROR(LOOKUP(2,1/((tblCompras[Produto]=$B31)*(tblCompras[Unid.]=$C31)*(tblCompras[Preço Unit.]=$E31)),tblCompras[Mercado]),"") -> Andre Supermercado | G31: =IFERROR(LOOKUP(2,1/((tblCompras[Produto]=$B31)*(tblCompras[Unid.]=$C31)*(tblCompras[Preço Unit.]=$E31)),tblCompras[Data]),"") -> 46152 | H31: =IFERROR(_xlfn.MAXIFS(tblCompras[Preço Unit.],tblCompras[Produto],$B31,tblCompras[Unid.],$C31),"") -> 10.2 | I31: =IFERROR(LOOKUP(2,1/((tblCompras[Produto]=$B31)*(tblCompras[Unid.]=$C31)*(tblCompras[Preço Unit.]=$H31)),tblCompras[Mercado]),"") -> Andre Supermercado | J31: =IFERROR(LOOKUP(2,1/((tblCompras[Produto]=$B31)*(tblCompras[Unid.]=$C31)*(tblCompras[Preço Unit.]=$H31)),tblCompras[Data]),"") -> 46152 | K31: =IF(OR($E31="",$H31=""),"",MAX(0,$H31-$E31)) -> 0 | L31: =IF(OR($E31="",$H31="",$E31=0),"",($H31-$E31)/$E31) -> 0 | M31: =IFERROR(LOOKUP(2,1/((tblCompras[Produto]=$B31)*(tblCompras[Unid.]=$C31)*(tblCompras[Data]=_xlfn.MAXIFS(tblCompras[Data],tblCompras[Produto],$B31,tblCompras[Unid.],$C31))),tblCompras[Preço Unit.]),"") -> 10.2 | N31: =IFERROR(LOOKUP(2,1/((tblCompras[Produto]=$B31)*(tblCompras[Unid.]=$C31)*(tblCompras[Data]=_xlfn.MAXIFS(tblCompras[Data],tblCompras[Produto],$B31,tblCompras[Unid.],$C31))),tblCompras[Mercado])&" · "&TEXT(DAY(_xlfn.MAXIFS(tblCompras[Data],tblCompras[Produto],$B31,tblCompras[Unid.],$C31)),"00")&"/"&TEXT(MONTH(_xlfn.MAXIFS(tblCompras[Data],tblCompras[Produto],$B31,tblCompras[Unid.],$C31)),"00")&"/"&TEXT(MOD(YEAR(_xlfn.MAXIFS(tblCompras[Data],tblCompras[Produto],$B31,tblCompras[Unid.],$C31)),100),"00"),"") -> Andre Supermercado · 10/05/26 | P31: =IF(AND(ISNUMBER($K31),$K31>0,OR($B$6="Todas",$D31=$B$6)),$K31+ROW()/100000,"")
B32: Power Mix Frutas 500ml | C32: UN | D32: Bebidas | E32: =IFERROR(_xlfn.MINIFS(tblCompras[Preço Unit.],tblCompras[Produto],$B32,tblCompras[Unid.],$C32),"") -> 6.4 | F32: =IFERROR(LOOKUP(2,1/((tblCompras[Produto]=$B32)*(tblCompras[Unid.]=$C32)*(tblCompras[Preço Unit.]=$E32)),tblCompras[Mercado]),"") -> Andre Eduardo Hipolito | G32: =IFERROR(LOOKUP(2,1/((tblCompras[Produto]=$B32)*(tblCompras[Unid.]=$C32)*(tblCompras[Preço Unit.]=$E32)),tblCompras[Data]),"") -> 46162 | H32: =IFERROR(_xlfn.MAXIFS(tblCompras[Preço Unit.],tblCompras[Produto],$B32,tblCompras[Unid.],$C32),"") -> 6.4 | I32: =IFERROR(LOOKUP(2,1/((tblCompras[Produto]=$B32)*(tblCompras[Unid.]=$C32)*(tblCompras[Preço Unit.]=$H32)),tblCompras[Mercado]),"") -> Andre Eduardo Hipolito | J32: =IFERROR(LOOKUP(2,1/((tblCompras[Produto]=$B32)*(tblCompras[Unid.]=$C32)*(tblCompras[Preço Unit.]=$H32)),tblCompras[Data]),"") -> 46162 | K32: =IF(OR($E32="",$H32=""),"",MAX(0,$H32-$E32)) -> 0 | L32: =IF(OR($E32="",$H32="",$E32=0),"",($H32-$E32)/$E32) -> 0 | M32: =IFERROR(LOOKUP(2,1/((tblCompras[Produto]=$B32)*(tblCompras[Unid.]=$C32)*(tblCompras[Data]=_xlfn.MAXIFS(tblCompras[Data],tblCompras[Produto],$B32,tblCompras[Unid.],$C32))),tblCompras[Preço Unit.]),"") -> 6.4 | N32: =IFERROR(LOOKUP(2,1/((tblCompras[Produto]=$B32)*(tblCompras[Unid.]=$C32)*(tblCompras[Data]=_xlfn.MAXIFS(tblCompras[Data],tblCompras[Produto],$B32,tblCompras[Unid.],$C32))),tblCompras[Mercado])&" · "&TEXT(DAY(_xlfn.MAXIFS(tblCompras[Data],tblCompras[Produto],$B32,tblCompras[Unid.],$C32)),"00")&"/"&TEXT(MONTH(_xlfn.MAXIFS(tblCompras[Data],tblCompras[Produto],$B32,tblCompras[Unid.],$C32)),"00")&"/"&TEXT(MOD(YEAR(_xlfn.MAXIFS(tblCompras[Data],tblCompras[Produto],$B32,tblCompras[Unid.],$C32)),100),"00"),"") -> Andre Eduardo Hipolito · 20/05/26 | P32: =IF(AND(ISNUMBER($K32),$K32>0,OR($B$6="Todas",$D32=$B$6)),$K32+ROW()/100000,"")
